<?xml version="1.0"?>
<robot xmlns:xacro="http://www.ros.org/wiki/xacro" name="vanir">

  <link name="base_link">
    <inertial>
      <origin xyz="0.0691514 0.00840293 0.0780423" rpy="0 0 0"/>
      <mass value="86.4984"/>
      <inertia ixx="1.23316" ixy="-2.70276e-05" ixz="-0.00435928" iyy="2.75808" iyz="1.88929e-06" izz="3.50466"/>
    </inertial>

    <!-- Part base_link -->
    <visual>
      <origin xyz="0.0684338 0.00840189 0.000920176" rpy="0 -0 1.5708"/>
      <geometry>
        <mesh filename="file://$(find vanir_description)/meshes/base_link.stl"/>
      </geometry>
      <material name="base_link_material">
        <color rgba="0.917647 0.917647 0.917647 1.0"/>
      </material>
    </visual>
    <collision>
      <origin xyz="0.0684338 0.00840189 0.000920176" rpy="0 -0 1.5708"/>
      <geometry>
        <mesh filename="file://$(find vanir_description)/meshes/base_link.stl"/>
      </geometry>
    </collision>
  </link>

  <!-- Right Wheel -->
  <link name="dof_wheel_r">
    <inertial>
      <origin xyz="-1.05949e-17 -8.8737e-19 -0.025" rpy="0 0 0"/>
      <mass value="0.908215"/>
      <inertia ixx="0.00138266" ixy="0" ixz="5.88417e-35" iyy="0.00138266" iyz="0" izz="0.0023869"/>
    </inertial>
    <visual>
      <origin xyz="-1.38778e-17 -4.44523e-18 0.1625" rpy="-1.5708 -1.5708 0"/>
      <geometry>
        <mesh filename="file://$(find vanir_description)/meshes/dof_wheel_r.stl"/>
      </geometry>
      <material name="dof_wheel_r_material">
        <color rgba="0.301961 0.301961 0.301961 1.0"/>
      </material>
    </visual>
    <collision>
      <origin xyz="-1.38778e-17 -4.44523e-18 0.1625" rpy="-1.5708 -1.5708 0"/>
      <geometry>
        <mesh filename="file://$(find vanir_description)/meshes/dof_wheel_r.stl"/>
      </geometry>
    </collision>
  </link>
  <joint name="wheel_l" type="continuous">
    <origin xyz="0.0684338 -0.2 -0.0" rpy="1.5708 0 0"/>
    <parent link="base_link"/>
    <child link="dof_wheel_r"/>
    <axis xyz="0 0 -1"/>
    <limit effort="10" velocity="10"/>
  </joint>

  <!-- Left Wheel -->
  <link name="dof_wheel_l">
    <inertial>
      <origin xyz="-3.28288e-18 -1.9388e-18 -0.025" rpy="0 0 0"/>
      <mass value="0.908215"/>
      <inertia ixx="0.00138266" ixy="0" ixz="-5.88417e-35" iyy="0.00138266" iyz="0" izz="0.0023869"/>
    </inertial>
    <visual>
      <origin xyz="1.38778e-17 4.44523e-18 0.1625" rpy="1.5708 1.5708 0"/>
      <geometry>
        <mesh filename="file://$(find vanir_description)/meshes/dof_wheel_l.stl"/>
      </geometry>
      <material name="dof_wheel_l_material">
        <color rgba="0.301961 0.301961 0.301961 1.0"/>
      </material>
    </visual>
    <collision>
      <origin xyz="1.38778e-17 4.44523e-18 0.1625" rpy="1.5708 1.5708 0"/>
      <geometry>
        <mesh filename="file://$(find vanir_description)/meshes/dof_wheel_l.stl"/>
      </geometry>
    </collision>
  </link>
  <joint name="wheel_r" type="continuous">
    <origin xyz="0.0684338 0.22 -0.0" rpy="-1.5708 0 0"/>
    <parent link="base_link"/>
    <child link="dof_wheel_l"/>
    <axis xyz="0 0 1"/>
    <limit effort="10" velocity="10"/>
  </joint>

  <!-- Camera -->
  <link name="vanir/base_link/depth_camera1">
    <visual>
      <origin xyz="0.0760324 0.00840189 0.000920176" rpy="0 0 1.5708"/>
      <geometry>
        <mesh filename="file://$(find vanir_description)/meshes/camera.stl"/>
      </geometry>
      <material name="camera_material">
        <color rgba="0.301961 0.290196 0.262745 1.0"/>
      </material>
    </visual>
    <collision>
      <origin xyz="0.0760324 0.00840189 0.000920176" rpy="0 0 1.5708"/>
      <geometry>
        <mesh filename="file://$(find vanir_description)/meshes/camera.stl"/>
      </geometry>
    </collision>
  </link>
  <joint name="camera_joint" type="fixed">
    <parent link="base_link"/>
    <child link="vanir/base_link/depth_camera1"/>
    <origin xyz="0.008 0.0 0.001" rpy="0 0 0"/>
  </joint>

  <!-- Lidar -->
  <link name="vanir/base_link/gpu_lidar">
    <visual>
      <origin xyz="0.0684338 0.00840189 0.000920176" rpy="0 0 1.5708"/>
      <geometry>
        <mesh filename="file://$(find vanir_description)/meshes/lidar.stl"/>
      </geometry>
      <material name="lidar_material">
        <color rgba="0.231373 0.380392 0.705882 1.0"/>
      </material>
    </visual>
    <collision>
      <origin xyz="0.0684338 0.00840189 0.000920176" rpy="0 0 1.5708"/>
      <geometry>
        <mesh filename="file://$(find vanir_description)/meshes/lidar.stl"/>
      </geometry>
    </collision>
  </link>
  <joint name="lidar_joint" type="fixed">
    <parent link="base_link"/>
    <child link="vanir/base_link/gpu_lidar"/>
    <origin xyz="-0.008 0.0 0.000920176" rpy="0 0 0"/>
  </joint>

<!-- Front Caster Sphere -->
<link name="front_caster">
  <inertial>
    <origin xyz="0 0 0" rpy="0 0 0"/>
    <mass value="0.1"/>
    <inertia ixx="1e-5" ixy="0" ixz="0" iyy="1e-5" iyz="0" izz="1e-5"/>
  </inertial>
  <visual>
    <origin xyz="0 0 0" rpy="0 0 0"/>
    <geometry>
      <sphere radius="0.07"/>
    </geometry>
    <material name="gray">
      <color rgba="0.5 0.5 0.5 1.0"/>
    </material>
  </visual>
  <collision>
    <origin xyz="0 0 0" rpy="0 0 0"/>
    <geometry>
      <sphere radius="0.07"/>
    </geometry>
  </collision>
</link>

<joint name="front_caster_joint" type="fixed">
  <parent link="base_link"/>
  <child link="front_caster"/>
  <origin xyz="0.28 0 0" rpy="0 0 0"/>
</joint>

<gazebo reference="front_caster">
  <mu1>0.0</mu1>
  <mu2>0.0</mu2>
  <material>Gazebo/Gray</material>
</gazebo>


<!-- Rear Caster Sphere -->
<link name="rear_caster">
  <inertial>
    <origin xyz="0 0 0" rpy="0 0 0"/>
    <mass value="0.1"/>
    <inertia ixx="1e-5" ixy="0" ixz="0" iyy="1e-5" iyz="0" izz="1e-5"/>
  </inertial>
  <visual>
    <origin xyz="0 0 0" rpy="0 0 0"/>
    <geometry>
      <sphere radius="0.07"/>
    </geometry>
    <material name="gray">
      <color rgba="0.5 0.5 0.5 1.0"/>
    </material>
  </visual>
  <collision>
    <origin xyz="0 0 0" rpy="0 0 0"/>
    <geometry>
      <sphere radius="0.07"/>
    </geometry>
  </collision>
</link>

<joint name="rear_caster_joint" type="fixed">
  <parent link="base_link"/>
  <child link="rear_caster"/>
  <origin xyz="-0.16 0 0" rpy="0 0 0"/>
</joint>

<gazebo reference="rear_caster">
  <mu1>0.0</mu1>
  <mu2>0.0</mu2>
  <material>Gazebo/Gray</material>
</gazebo>

</robot>
